[2024-09-08T20:30:13.802+0000] {taskinstance.py:1087} INFO - Dependencies all met for <TaskInstance: ml_pipeline.download_data_from_s3 manual__2024-09-08T20:30:11.800910+00:00 [queued]>
[2024-09-08T20:30:13.809+0000] {taskinstance.py:1087} INFO - Dependencies all met for <TaskInstance: ml_pipeline.download_data_from_s3 manual__2024-09-08T20:30:11.800910+00:00 [queued]>
[2024-09-08T20:30:13.809+0000] {taskinstance.py:1283} INFO - 
--------------------------------------------------------------------------------
[2024-09-08T20:30:13.809+0000] {taskinstance.py:1284} INFO - Starting attempt 1 of 2
[2024-09-08T20:30:13.809+0000] {taskinstance.py:1285} INFO - 
--------------------------------------------------------------------------------
[2024-09-08T20:30:13.820+0000] {taskinstance.py:1304} INFO - Executing <Task(PythonOperator): download_data_from_s3> on 2024-09-08 20:30:11.800910+00:00
[2024-09-08T20:30:13.825+0000] {standard_task_runner.py:55} INFO - Started process 153 to run task
[2024-09-08T20:30:13.827+0000] {standard_task_runner.py:82} INFO - Running: ['***', 'tasks', 'run', 'ml_pipeline', 'download_data_from_s3', 'manual__2024-09-08T20:30:11.800910+00:00', '--job-id', '111', '--raw', '--subdir', 'DAGS_FOLDER/ml_pipeline_dag.py', '--cfg-path', '/tmp/tmpllfi1svf']
[2024-09-08T20:30:13.829+0000] {standard_task_runner.py:83} INFO - Job 111: Subtask download_data_from_s3
[2024-09-08T20:30:13.871+0000] {task_command.py:389} INFO - Running <TaskInstance: ml_pipeline.download_data_from_s3 manual__2024-09-08T20:30:11.800910+00:00 [running]> on host 9e89577dd217
[2024-09-08T20:30:13.920+0000] {taskinstance.py:1513} INFO - Exporting the following env vars:
AIRFLOW_CTX_DAG_OWNER=***
AIRFLOW_CTX_DAG_ID=ml_pipeline
AIRFLOW_CTX_TASK_ID=download_data_from_s3
AIRFLOW_CTX_EXECUTION_DATE=2024-09-08T20:30:11.800910+00:00
AIRFLOW_CTX_TRY_NUMBER=1
AIRFLOW_CTX_DAG_RUN_ID=manual__2024-09-08T20:30:11.800910+00:00
[2024-09-08T20:30:14.323+0000] {taskinstance.py:1772} ERROR - Task failed with exception
Traceback (most recent call last):
  File "/home/airflow/.local/lib/python3.7/site-packages/airflow/operators/python.py", line 175, in execute
    return_value = self.execute_callable()
  File "/home/airflow/.local/lib/python3.7/site-packages/airflow/operators/python.py", line 192, in execute_callable
    return self.python_callable(*self.op_args, **self.op_kwargs)
  File "/opt/airflow/dags/ml_pipeline_dag.py", line 10, in download_data_from_s3
    s3.download_file('big-mart-sales-data', 'raw_data/train.csv', '/tmp/train.csv')
  File "/home/airflow/.local/lib/python3.7/site-packages/boto3/s3/inject.py", line 195, in download_file
    callback=Callback,
  File "/home/airflow/.local/lib/python3.7/site-packages/boto3/s3/transfer.py", line 320, in download_file
    future.result()
  File "/home/airflow/.local/lib/python3.7/site-packages/s3transfer/futures.py", line 103, in result
    return self._coordinator.result()
  File "/home/airflow/.local/lib/python3.7/site-packages/s3transfer/futures.py", line 266, in result
    raise self._exception
  File "/home/airflow/.local/lib/python3.7/site-packages/s3transfer/tasks.py", line 269, in _main
    self._submit(transfer_future=transfer_future, **kwargs)
  File "/home/airflow/.local/lib/python3.7/site-packages/s3transfer/download.py", line 357, in _submit
    **transfer_future.meta.call_args.extra_args,
  File "/home/airflow/.local/lib/python3.7/site-packages/botocore/client.py", line 530, in _api_call
    return self._make_api_call(operation_name, kwargs)
  File "/home/airflow/.local/lib/python3.7/site-packages/botocore/client.py", line 944, in _make_api_call
    operation_model, request_dict, request_context
  File "/home/airflow/.local/lib/python3.7/site-packages/botocore/client.py", line 966, in _make_request
    return self._endpoint.make_request(operation_model, request_dict)
  File "/home/airflow/.local/lib/python3.7/site-packages/botocore/endpoint.py", line 119, in make_request
    return self._send_request(request_dict, operation_model)
  File "/home/airflow/.local/lib/python3.7/site-packages/botocore/endpoint.py", line 198, in _send_request
    request = self.create_request(request_dict, operation_model)
  File "/home/airflow/.local/lib/python3.7/site-packages/botocore/endpoint.py", line 137, in create_request
    operation_name=operation_model.name,
  File "/home/airflow/.local/lib/python3.7/site-packages/botocore/hooks.py", line 412, in emit
    return self._emitter.emit(aliased_event_name, **kwargs)
  File "/home/airflow/.local/lib/python3.7/site-packages/botocore/hooks.py", line 256, in emit
    return self._emit(event_name, kwargs)
  File "/home/airflow/.local/lib/python3.7/site-packages/botocore/hooks.py", line 239, in _emit
    response = handler(**kwargs)
  File "/home/airflow/.local/lib/python3.7/site-packages/botocore/signers.py", line 105, in handler
    return self.sign(operation_name, request)
  File "/home/airflow/.local/lib/python3.7/site-packages/botocore/signers.py", line 189, in sign
    auth.add_auth(request)
  File "/home/airflow/.local/lib/python3.7/site-packages/botocore/auth.py", line 418, in add_auth
    raise NoCredentialsError()
botocore.exceptions.NoCredentialsError: Unable to locate credentials
[2024-09-08T20:30:14.329+0000] {taskinstance.py:1327} INFO - Marking task as UP_FOR_RETRY. dag_id=ml_pipeline, task_id=download_data_from_s3, execution_date=20240908T203011, start_date=20240908T203013, end_date=20240908T203014
[2024-09-08T20:30:14.341+0000] {standard_task_runner.py:105} ERROR - Failed to execute job 111 for task download_data_from_s3 (Unable to locate credentials; 153)
[2024-09-08T20:30:14.361+0000] {local_task_job.py:159} INFO - Task exited with return code 1
[2024-09-08T20:30:14.380+0000] {taskinstance.py:2582} INFO - 0 downstream tasks scheduled from follow-on schedule check
