[2024-09-08T00:05:33.955+0000] {taskinstance.py:1087} INFO - Dependencies all met for <TaskInstance: ml_pipeline.train_model scheduled__2024-09-07T00:00:00+00:00 [queued]>
[2024-09-08T00:05:33.962+0000] {taskinstance.py:1087} INFO - Dependencies all met for <TaskInstance: ml_pipeline.train_model scheduled__2024-09-07T00:00:00+00:00 [queued]>
[2024-09-08T00:05:33.962+0000] {taskinstance.py:1283} INFO - 
--------------------------------------------------------------------------------
[2024-09-08T00:05:33.963+0000] {taskinstance.py:1284} INFO - Starting attempt 2 of 2
[2024-09-08T00:05:33.963+0000] {taskinstance.py:1285} INFO - 
--------------------------------------------------------------------------------
[2024-09-08T00:05:33.975+0000] {taskinstance.py:1304} INFO - Executing <Task(PythonOperator): train_model> on 2024-09-07 00:00:00+00:00
[2024-09-08T00:05:33.978+0000] {standard_task_runner.py:55} INFO - Started process 68 to run task
[2024-09-08T00:05:33.981+0000] {standard_task_runner.py:82} INFO - Running: ['***', 'tasks', 'run', 'ml_pipeline', 'train_model', 'scheduled__2024-09-07T00:00:00+00:00', '--job-id', '22', '--raw', '--subdir', 'DAGS_FOLDER/ml_pipeline_dag.py', '--cfg-path', '/tmp/tmpo5snb_ai']
[2024-09-08T00:05:33.982+0000] {standard_task_runner.py:83} INFO - Job 22: Subtask train_model
[2024-09-08T00:05:34.028+0000] {task_command.py:389} INFO - Running <TaskInstance: ml_pipeline.train_model scheduled__2024-09-07T00:00:00+00:00 [running]> on host 394f8fce6b56
[2024-09-08T00:05:34.222+0000] {taskinstance.py:1513} INFO - Exporting the following env vars:
AIRFLOW_CTX_DAG_OWNER=***
AIRFLOW_CTX_DAG_ID=ml_pipeline
AIRFLOW_CTX_TASK_ID=train_model
AIRFLOW_CTX_EXECUTION_DATE=2024-09-07T00:00:00+00:00
AIRFLOW_CTX_TRY_NUMBER=2
AIRFLOW_CTX_DAG_RUN_ID=scheduled__2024-09-07T00:00:00+00:00
[2024-09-08T00:05:34.222+0000] {taskinstance.py:1772} ERROR - Task failed with exception
Traceback (most recent call last):
  File "/home/airflow/.local/lib/python3.7/site-packages/airflow/operators/python.py", line 175, in execute
    return_value = self.execute_callable()
  File "/home/airflow/.local/lib/python3.7/site-packages/airflow/operators/python.py", line 192, in execute_callable
    return self.python_callable(*self.op_args, **self.op_kwargs)
  File "/opt/airflow/dags/ml_pipeline_dag.py", line 23, in train_model
    from sklearn.ensemble import RandomForestRegressor
ModuleNotFoundError: No module named 'sklearn'
[2024-09-08T00:05:34.228+0000] {taskinstance.py:1327} INFO - Marking task as FAILED. dag_id=ml_pipeline, task_id=train_model, execution_date=20240907T000000, start_date=20240908T000533, end_date=20240908T000534
[2024-09-08T00:05:34.236+0000] {standard_task_runner.py:105} ERROR - Failed to execute job 22 for task train_model (No module named 'sklearn'; 68)
[2024-09-08T00:05:34.274+0000] {local_task_job.py:159} INFO - Task exited with return code 1
[2024-09-08T00:05:34.291+0000] {taskinstance.py:2582} INFO - 0 downstream tasks scheduled from follow-on schedule check
[2024-09-08T00:18:34.303+0000] {taskinstance.py:1087} INFO - Dependencies all met for <TaskInstance: ml_pipeline.train_model scheduled__2024-09-07T00:00:00+00:00 [queued]>
[2024-09-08T00:18:34.311+0000] {taskinstance.py:1087} INFO - Dependencies all met for <TaskInstance: ml_pipeline.train_model scheduled__2024-09-07T00:00:00+00:00 [queued]>
[2024-09-08T00:18:34.312+0000] {taskinstance.py:1283} INFO - 
--------------------------------------------------------------------------------
[2024-09-08T00:18:34.312+0000] {taskinstance.py:1284} INFO - Starting attempt 2 of 2
[2024-09-08T00:18:34.312+0000] {taskinstance.py:1285} INFO - 
--------------------------------------------------------------------------------
[2024-09-08T00:18:34.328+0000] {taskinstance.py:1304} INFO - Executing <Task(PythonOperator): train_model> on 2024-09-07 00:00:00+00:00
[2024-09-08T00:18:34.333+0000] {standard_task_runner.py:55} INFO - Started process 102 to run task
[2024-09-08T00:18:34.335+0000] {standard_task_runner.py:82} INFO - Running: ['***', 'tasks', 'run', 'ml_pipeline', 'train_model', 'scheduled__2024-09-07T00:00:00+00:00', '--job-id', '36', '--raw', '--subdir', 'DAGS_FOLDER/ml_pipeline_dag.py', '--cfg-path', '/tmp/tmpk4jl9b8e']
[2024-09-08T00:18:34.337+0000] {standard_task_runner.py:83} INFO - Job 36: Subtask train_model
[2024-09-08T00:18:34.381+0000] {task_command.py:389} INFO - Running <TaskInstance: ml_pipeline.train_model scheduled__2024-09-07T00:00:00+00:00 [running]> on host c937658a3a75
[2024-09-08T00:18:34.433+0000] {taskinstance.py:1513} INFO - Exporting the following env vars:
AIRFLOW_CTX_DAG_OWNER=***
AIRFLOW_CTX_DAG_ID=ml_pipeline
AIRFLOW_CTX_TASK_ID=train_model
AIRFLOW_CTX_EXECUTION_DATE=2024-09-07T00:00:00+00:00
AIRFLOW_CTX_TRY_NUMBER=2
AIRFLOW_CTX_DAG_RUN_ID=scheduled__2024-09-07T00:00:00+00:00
[2024-09-08T00:18:34.434+0000] {taskinstance.py:1772} ERROR - Task failed with exception
Traceback (most recent call last):
  File "/home/airflow/.local/lib/python3.7/site-packages/airflow/operators/python.py", line 175, in execute
    return_value = self.execute_callable()
  File "/home/airflow/.local/lib/python3.7/site-packages/airflow/operators/python.py", line 192, in execute_callable
    return self.python_callable(*self.op_args, **self.op_kwargs)
  File "/opt/airflow/dags/ml_pipeline_dag.py", line 23, in train_model
    from sklearn.ensemble import RandomForestRegressor
ModuleNotFoundError: No module named 'sklearn'
[2024-09-08T00:18:34.438+0000] {taskinstance.py:1327} INFO - Marking task as FAILED. dag_id=ml_pipeline, task_id=train_model, execution_date=20240907T000000, start_date=20240908T001834, end_date=20240908T001834
[2024-09-08T00:18:34.449+0000] {standard_task_runner.py:105} ERROR - Failed to execute job 36 for task train_model (No module named 'sklearn'; 102)
[2024-09-08T00:18:34.467+0000] {local_task_job.py:159} INFO - Task exited with return code 1
[2024-09-08T00:18:34.484+0000] {taskinstance.py:2582} INFO - 0 downstream tasks scheduled from follow-on schedule check
[2024-09-08T01:46:56.344+0000] {taskinstance.py:1087} INFO - Dependencies all met for <TaskInstance: ml_pipeline.train_model scheduled__2024-09-07T00:00:00+00:00 [queued]>
[2024-09-08T01:46:56.352+0000] {taskinstance.py:1087} INFO - Dependencies all met for <TaskInstance: ml_pipeline.train_model scheduled__2024-09-07T00:00:00+00:00 [queued]>
[2024-09-08T01:46:56.352+0000] {taskinstance.py:1283} INFO - 
--------------------------------------------------------------------------------
[2024-09-08T01:46:56.352+0000] {taskinstance.py:1284} INFO - Starting attempt 2 of 2
[2024-09-08T01:46:56.352+0000] {taskinstance.py:1285} INFO - 
--------------------------------------------------------------------------------
[2024-09-08T01:46:56.364+0000] {taskinstance.py:1304} INFO - Executing <Task(PythonOperator): train_model> on 2024-09-07 00:00:00+00:00
[2024-09-08T01:46:56.369+0000] {standard_task_runner.py:55} INFO - Started process 324 to run task
[2024-09-08T01:46:56.372+0000] {standard_task_runner.py:82} INFO - Running: ['***', 'tasks', 'run', 'ml_pipeline', 'train_model', 'scheduled__2024-09-07T00:00:00+00:00', '--job-id', '79', '--raw', '--subdir', 'DAGS_FOLDER/ml_pipeline_dag.py', '--cfg-path', '/tmp/tmph4_zfl9q']
[2024-09-08T01:46:56.373+0000] {standard_task_runner.py:83} INFO - Job 79: Subtask train_model
[2024-09-08T01:46:56.421+0000] {task_command.py:389} INFO - Running <TaskInstance: ml_pipeline.train_model scheduled__2024-09-07T00:00:00+00:00 [running]> on host 0ef1cf3b829d
[2024-09-08T01:46:56.612+0000] {taskinstance.py:1513} INFO - Exporting the following env vars:
AIRFLOW_CTX_DAG_OWNER=***
AIRFLOW_CTX_DAG_ID=ml_pipeline
AIRFLOW_CTX_TASK_ID=train_model
AIRFLOW_CTX_EXECUTION_DATE=2024-09-07T00:00:00+00:00
AIRFLOW_CTX_TRY_NUMBER=2
AIRFLOW_CTX_DAG_RUN_ID=scheduled__2024-09-07T00:00:00+00:00
[2024-09-08T01:46:56.613+0000] {taskinstance.py:1772} ERROR - Task failed with exception
Traceback (most recent call last):
  File "/home/airflow/.local/lib/python3.7/site-packages/airflow/operators/python.py", line 175, in execute
    return_value = self.execute_callable()
  File "/home/airflow/.local/lib/python3.7/site-packages/airflow/operators/python.py", line 192, in execute_callable
    return self.python_callable(*self.op_args, **self.op_kwargs)
  File "/opt/airflow/dags/ml_pipeline_dag.py", line 23, in train_model
    from sklearn.ensemble import RandomForestRegressor
ModuleNotFoundError: No module named 'sklearn'
[2024-09-08T01:46:56.619+0000] {taskinstance.py:1327} INFO - Marking task as FAILED. dag_id=ml_pipeline, task_id=train_model, execution_date=20240907T000000, start_date=20240908T014656, end_date=20240908T014656
[2024-09-08T01:46:56.630+0000] {standard_task_runner.py:105} ERROR - Failed to execute job 79 for task train_model (No module named 'sklearn'; 324)
[2024-09-08T01:46:56.664+0000] {local_task_job.py:159} INFO - Task exited with return code 1
[2024-09-08T01:46:56.688+0000] {taskinstance.py:2582} INFO - 0 downstream tasks scheduled from follow-on schedule check
